<?xml version="1.0" ?>
<robot name="orne_box" xmlns:xacro="http://www.ros.org/wiki/xacro">
  <xacro:arg name="ignition_gazebo" default="false"/>
  <xacro:property name="PI" value="3.1415926535897931"/>
  <xacro:include filename="$(find orne_box_description)/urdf/orne_box.urdf.xacro" />
  <xacro:include filename="$(find lidar_with_mirror_description)/urdf/orne_box_lidar_with_mirror.gazebo.xacro"/>
  <xacro:include filename="$(find orne_box_description)/urdf/sensors/hokuyo.urdf.xacro"/>

  <xacro:sensor_hokuyo name="hokuyo_with_mirror" parent="base_link" size="0.05 0.05 0.05">
    <origin xyz="0.374295 0 0.2185" rpy="${-PI} 0 0"/>
  </xacro:sensor_hokuyo>

  <joint name="lidar_with_mirror_prismatic_joint" type="prismatic">
    <parent link="base_link"/>
    <child link="lidar_with_mirror_prismatic_link"/>
    <origin xyz="1.0 0 0.3" rpy="0 0 0"/>
    <axis xyz="0 0 1"/>
    <limit effort="100" velocity="100.0" lower="-0.3" upper="1" />
  </joint>
  <link name="lidar_with_mirror_prismatic_link">
    <inertial>
      <origin xyz="0 0 0" />
      <mass value="0.2" />
      <inertia ixx="0.1" ixy="0.0" ixz="0.0" iyy="0.1" iyz="0.0" izz="0.1" />
    </inertial>
  </link>

  <joint name="lidar_with_mirror_pitch_joint" type="revolute">
    <parent link="lidar_with_mirror_prismatic_link"/>
    <child link="lidar_with_mirror_pitch_link"/>
    <origin xyz="0 0 0" rpy="0 ${PI/9} 0"/>
    <axis xyz="0 1 0"/>
    <limit effort="100" velocity="100.0" lower="${-PI}" upper="${PI}" />
  </joint>
  <link name="lidar_with_mirror_pitch_link">
    <inertial>
      <origin xyz="0 0 0" />
      <mass value="0.2" />
      <inertia ixx="0.1" ixy="0.0" ixz="0.0" iyy="0.1" iyz="0.0" izz="0.1" />
    </inertial>
  </link>

  <joint name="lidar_with_mirror_roll_joint" type="revolute">
    <parent link="lidar_with_mirror_pitch_link"/>
    <child link="lidar_with_mirror_roll_link"/>
    <origin xyz="0 0 0" rpy="0 0 0"/>
    <axis xyz="1 0 0"/>
    <limit effort="100" velocity="100.0" lower="${-PI}" upper="${PI}" />
  </joint>
  <link name="lidar_with_mirror_roll_link">
    <inertial>
      <origin xyz="0 0 0" />
      <mass value="0.2" />
      <inertia ixx="0.1" ixy="0.0" ixz="0.0" iyy="0.1" iyz="0.0" izz="0.1" />
    </inertial>
  </link>

  <xacro:property name="len0" value="0.1" />
  <xacro:property name="front" value="0" />
  <xacro:property name="height" value="0" />

  <xacro:sensor_hokuyo name="lidar_with_mirror_center" parent="lidar_with_mirror_roll_link" size="0.05 0.05 0.05">
    <origin xyz="${front} 0 ${height}" rpy="0 0 0"/>
  </xacro:sensor_hokuyo>

  <joint name="lidar_with_mirror_mirror1_roll_joint" type="revolute">
    <parent link="lidar_with_mirror_center_link"/>
    <child link="lidar_with_mirror_mirror1_roll_link"/>
    <origin xyz="0 ${len0} 0" rpy="${-PI/4} 0 0"/>
    <axis xyz="-1 0 0"/>
    <limit effort="100" velocity="100.0" lower="${-PI}" upper="${PI}" />
  </joint>
  <link name="lidar_with_mirror_mirror1_roll_link">
    <inertial>
      <origin xyz="0 0 0" />
      <mass value="0.2" />
      <inertia ixx="0.1" ixy="0.0" ixz="0.0" iyy="0.1" iyz="0.0" izz="0.1" />
    </inertial>
  </link>

  <xacro:sensor_hokuyo name="lidar_with_mirror_left" parent="lidar_with_mirror_mirror1_roll_link"  size="0.05 0.05 0.05">
    <origin xyz="0 ${-len0} 0" rpy="0 0 0"/>
  </xacro:sensor_hokuyo>

  <joint name="lidar_with_mirror_mirror2_roll_joint" type="revolute">
    <parent link="lidar_with_mirror_center_link"/>
    <child link="lidar_with_mirror_mirror2_roll_link"/>
    <origin xyz="0 ${-len0} 0" rpy="${PI/4} 0 0"/>
    <axis xyz="1 0 0"/>
    <limit effort="100" velocity="100.0" lower="${-PI}" upper="${PI}" />
  </joint>
  <link name="lidar_with_mirror_mirror2_roll_link">
    <inertial>
      <origin xyz="0 0 0" />
      <mass value="0.2" />
      <inertia ixx="0.1" ixy="0.0" ixz="0.0" iyy="0.1" iyz="0.0" izz="0.1" />
    </inertial>
  </link>

  <xacro:sensor_hokuyo name="lidar_with_mirror_right" parent="lidar_with_mirror_mirror2_roll_link"  size="0.05 0.05 0.05">
    <origin xyz="0 ${len0} 0" rpy="0 0 0"/>
  </xacro:sensor_hokuyo>

  <transmission name="tran1">
    <type>transmission_interface/SimpleTransmission</type>
    <joint name="left_wheel_hinge">
      <hardwareInterface>hardware_interface/VelocityJointInterface</hardwareInterface>
    </joint>
  <actuator name="left_motor">
      <hardwareInterface>hardware_interface/VelocityJointInterface</hardwareInterface>
      <mechanicalReduction>1</mechanicalReduction>
    </actuator>
  </transmission>

  <transmission name="tran2">
    <type>transmission_interface/SimpleTransmission</type>
    <joint name="right_wheel_hinge">
      <hardwareInterface>hardware_interface/VelocityJointInterface</hardwareInterface>
    </joint>  
  <actuator name="right_motor">
      <hardwareInterface>hardware_interface/VelocityJointInterface</hardwareInterface>
      <mechanicalReduction>1</mechanicalReduction>
    </actuator>
  </transmission>

  <transmission name="tran3">
    <type>transmission_interface/SimpleTransmission</type>
    <joint name="lidar_with_mirror_pitch_joint">
      <hardwareInterface>hardware_interface/PositionJointInterface</hardwareInterface>
    </joint>
  <actuator name="lidar_with_mirror_pitch_motor">
      <hardwareInterface>hardware_interface/PositionJointInterface</hardwareInterface>
      <mechanicalReduction>1</mechanicalReduction>
    </actuator>
  </transmission>

  <transmission name="tran4">
    <type>transmission_interface/SimpleTransmission</type>
    <joint name="lidar_with_mirror_roll_joint">
      <hardwareInterface>hardware_interface/PositionJointInterface</hardwareInterface>
    </joint>
  <actuator name="lidar_with_mirror_roll_motor">
      <hardwareInterface>hardware_interface/PositionJointInterface</hardwareInterface>
      <mechanicalReduction>1</mechanicalReduction>
    </actuator>
  </transmission>

  <transmission name="tran5">
    <type>transmission_interface/SimpleTransmission</type>
    <joint name="lidar_with_mirror_mirror1_roll_joint">
      <hardwareInterface>hardware_interface/PositionJointInterface</hardwareInterface>
    </joint>
  <actuator name="lidar_with_mirror_mirror1_roll_motor">
      <hardwareInterface>hardware_interface/PositionJointInterface</hardwareInterface>
      <mechanicalReduction>1</mechanicalReduction>
    </actuator>
  </transmission>

  <transmission name="tran6">
    <type>transmission_interface/SimpleTransmission</type>
    <joint name="lidar_with_mirror_mirror2_roll_joint">
      <hardwareInterface>hardware_interface/PositionJointInterface</hardwareInterface>
    </joint>
  <actuator name="lidar_with_mirror_mirror2_roll_motor">
      <hardwareInterface>hardware_interface/PositionJointInterface</hardwareInterface>
      <mechanicalReduction>1</mechanicalReduction>
    </actuator>
  </transmission>

  <transmission name="tran7">
    <type>transmission_interface/SimpleTransmission</type>
    <joint name="lidar_with_mirror_prismatic_joint">
      <hardwareInterface>hardware_interface/PositionJointInterface</hardwareInterface>
    </joint>
  <actuator name="lidar_with_mirror_prismatic_motor">
      <hardwareInterface>hardware_interface/PositionJointInterface</hardwareInterface>
      <mechanicalReduction>1</mechanicalReduction>
    </actuator>
  </transmission>

</robot>
