<?xml version="1.0" ?>
<robot name="orne_box" xmlns:xacro="http://www.ros.org/wiki/xacro">
  <xacro:property name="PI" value="3.1415926535897931"/>
  <xacro:include filename="$(find icart_mini_description)/urdf/materials.xacro" />
  <xacro:include filename="$(find lidar_with_mirror_description)/urdf/orne_box_lidar_with_mirror.gazebo.xacro"/>

  <link name="base_link">
    <visual>
      <origin xyz="0.090 0 0.1715" rpy="0 0 0"/>
      <geometry>
        <box size="0.400 0.404 0.202"/>
      </geometry>
      <material name="orange"/>
    </visual>
    <visual>
      <origin xyz="0.36125 0 0.2625" rpy="0 0 0"/>
      <geometry>
        <box size="0.1425 0.404 0.020"/>
      </geometry>
      <material name="orange"/>
    </visual>
    <visual>
      <origin xyz="0.35625 0 0.156" rpy="0 0 0"/>
      <geometry>
        <box size="0.1325 0.404 0.020"/>
      </geometry>
      <material name="orange"/>
    </visual>
    <visual>
      <origin xyz="-0.120 0 0.4815" rpy="0 0 0"/>
      <geometry>
        <box size="0.020 0.404 0.822"/>
      </geometry>
      <material name="orange"/>
    </visual>
    
<!--
    <collision>
      <origin xyz="0.090 0 0.1715" rpy="0 0 0"/>
      <geometry>
        <box size="0.400 0.404 0.202"/>
      </geometry>
    </collision>
    <collision>
      <origin xyz="0.36125 0 0.2625" rpy="0 0 0"/>
      <geometry>
        <box size="0.1425 0.404 0.020"/>
      </geometry>
    </collision>
    <collision>
      <origin xyz="0.35625 0 0.156" rpy="0 0 0"/>
      <geometry>
        <box size="0.1325 0.404 0.020"/>
      </geometry>
    </collision>
    <collision>
      <origin xyz="-0.120 0 0.4815" rpy="0 0 0"/>
      <geometry>
        <box size="0.020 0.404 0.822"/>
      </geometry>
    </collision>
-->
    <inertial>
      <origin xyz="0.090 0 0.1715" rpy="0 0 0"/>
      <mass value="25.0"/>
      <inertia ixx="1.0" ixy="0.0" ixz="0.0" iyy="1.0" iyz="0.0" izz="1.0" />
    </inertial>
  </link>


  <joint name="wheel_hinge" type="revolute">
    <parent link="base_link"/>
    <child link="wheel_link"/>
    <origin xyz="0.0 0.0 0.152" rpy="0 0 0"/>
    <axis xyz="1 0 0"/>
    <limit effort="100" velocity="100.0"  lower="-5000" upper="5000" />
  </joint>

  <link name="wheel_link">
    <inertial>
      <origin xyz="0 0 0" />
      <mass value="0.2" />
      <inertia ixx="0.1" ixy="0.0" ixz="0.0" iyy="0.1" iyz="0.0" izz="0.1" />
    </inertial>
  </link>

  <joint name="left_wheel_hinge" type="revolute">
    <parent link="wheel_link"/>
    <child link="wheel_left_link"/>
    <origin xyz="0.0 0.23075 0.0" rpy="${-PI/2} 0 0"/>
    <axis xyz="0 0 1"/>
    <limit effort="100" velocity="100.0"  lower="-5000" upper="5000" />
  </joint>

  <link name="wheel_left_link">
    <visual>
      <origin xyz="0 0 0" rpy="0 0 0"/>
      <geometry>
        <mesh filename="package://lidar_with_mirror_description/meshes/wheels/tire.stl" scale="1 1 1"/>
      </geometry>
<!--
      <origin xyz="0 0 0" rpy="0 0 0"/>
      <geometry>
        <cylinder length="0.045" radius="0.152"/>
      </geometry>
-->
      <material name="white"/>
    </visual>

    <collision>
      <origin xyz="0 0 0" rpy="0 0 0"/>
      <geometry>
        <cylinder length="0.045" radius="0.152"/>
      </geometry>
    </collision>

    <inertial>
      <origin xyz="0 0 0" />
      <mass value="0.2" />
      <inertia ixx="0.1" ixy="0.0" ixz="0.0" iyy="0.1" iyz="0.0" izz="0.1" />
    </inertial>

  </link>

  <joint name="right_wheel_hinge" type="revolute">
    <parent link="wheel_link"/>
    <child link="wheel_right_link"/>
    <origin xyz="0.0 -0.23075 0.0" rpy="${-PI/2} 0 0"/>
    <axis xyz="0 0 1"/>
    <limit effort="100" velocity="100.0"  lower="-5000" upper="5000" />
  </joint>

  <link name="wheel_right_link">
    <visual>
      <origin xyz="0 0 0" rpy="0 0 0"/>
      <geometry>
        <mesh filename="package://lidar_with_mirror_description/meshes/wheels/tire.stl" scale="1 1 1"/>
      </geometry>
<!--
      <origin xyz="0 0 0" rpy="0 0 0"/>
      <geometry>
        <cylinder length="0.045" radius="0.152"/>
      </geometry>
-->
      <material name="white"/>
    </visual>

    <collision>
      <origin xyz="0 0 0" rpy="0 0 0"/>
      <geometry>
        <cylinder length="0.045" radius="0.152"/>
      </geometry>
    </collision>

    <inertial>
      <origin xyz="0 0 0" />
      <mass value="0.2" />
      <inertia ixx="0.1" ixy="0.0" ixz="0.0" iyy="0.1" iyz="0.0" izz="0.1" />
    </inertial>

  </link>

  <joint name="caster_front_joint" type="prismatic">
    <parent link="base_link"/>
    <child link="caster_front_link"/>
    <origin xyz="0.362 0 0.050" rpy="0 0 0"/>
    <axis xyz="0 0 1"/>
    <limit effort="100" velocity="100.0" lower="-1" upper="1" />
  </joint>

  <link name="caster_front_link">
    <visual>
      <origin xyz="0 0.150 0" rpy="${PI/2} 0 0"/>
      <geometry>
        <cylinder length="0.025" radius="0.050"/>
      </geometry>
      <material name="red"/>
    </visual>
    <visual>
      <origin xyz="0 -0.150 0" rpy="${PI/2} 0 0"/>
      <geometry>
        <cylinder length="0.025" radius="0.050"/>
      </geometry>
      <material name="red"/>
    </visual>

    <collision>
      <origin xyz="0 0.150 0" rpy="${PI/2} 0 0"/>
      <geometry>
        <cylinder length="0.025" radius="0.050"/>
      </geometry>
    </collision>
    <collision>
      <origin xyz="0 -0.150 0" rpy="${PI/2} 0 0"/>
      <geometry>
        <cylinder length="0.025" radius="0.050"/>
      </geometry>
    </collision>

    <inertial>
      <origin xyz="0 0 0" />
      <mass value="0.2" />
      <inertia ixx="0.1" ixy="0.0" ixz="0.0" iyy="0.1" iyz="0.0" izz="0.1" />
    </inertial>
  </link>

  <xacro:include filename="$(find icart_mini_description)/urdf/sensors/imu.urdf.xacro"/>
  <!-- Setting for imu -->
  <xacro:sensor_imu name="imu" parent="base_link" size="0.05 0.05 0.05">
    <origin xyz="0.3 0 0.2445" rpy="0 0 ${-PI/2}"/>
  </xacro:sensor_imu>

  <!-- Setting for 2D-LiDAR -->
  <xacro:include filename="$(find icart_mini_description)/urdf/sensors/hokuyo.urdf.xacro"/>
  <xacro:sensor_hokuyo name="hokuyo" parent="base_link">
    <origin xyz="0.374295 0 0.2185" rpy="${-PI} 0 0"/>
  </xacro:sensor_hokuyo>

  <!-- Setting for Lidar with mirror -->
  <joint name="lidar_with_mirror_prismatic_joint" type="prismatic">
    <parent link="base_link"/>
    <child link="lidar_with_mirror_prismatic_link"/>
    <origin xyz="0.43 0.0 0.34" rpy="0 0 0"/>
    <axis xyz="0 0 1"/>
    <limit effort="100" velocity="100.0" lower="-0.3" upper="1" />
  </joint>
  <link name="lidar_with_mirror_prismatic_link">
    <inertial>
      <origin xyz="0 0 0" />
      <mass value="0.01" />
      <inertia ixx="0.1" ixy="0.0" ixz="0.0" iyy="0.1" iyz="0.0" izz="0.1" />
    </inertial>
  </link>

  <joint name="lidar_with_mirror_pitch_joint" type="revolute">
    <parent link="lidar_with_mirror_prismatic_link"/>
    <child link="lidar_with_mirror_pitch_link"/>
    <origin xyz="0 0 0" rpy="0 0.314 0"/>
    <axis xyz="0 1 0"/>
    <limit effort="100" velocity="100.0" lower="${-PI}" upper="${PI}" />
  </joint>
  <link name="lidar_with_mirror_pitch_link">
    <inertial>
      <origin xyz="0 0 0" />
      <mass value="0.01" />
      <inertia ixx="0.1" ixy="0.0" ixz="0.0" iyy="0.1" iyz="0.0" izz="0.1" />
    </inertial>
  </link>

  <joint name="lidar_with_mirror_roll_joint" type="revolute">
    <parent link="lidar_with_mirror_pitch_link"/>
    <child link="lidar_with_mirror_roll_link"/>
    <origin xyz="0 0 0" rpy="0 0 0"/>
    <axis xyz="1 0 0"/>
    <limit effort="100" velocity="100.0" lower="${-PI}" upper="${PI}" />
  </joint>
  <link name="lidar_with_mirror_roll_link">
    <inertial>
      <origin xyz="0 0 0" />
      <mass value="0.01" />
      <inertia ixx="0.1" ixy="0.0" ixz="0.0" iyy="0.1" iyz="0.0" izz="0.1" />
    </inertial>
  </link>

  <xacro:include filename="$(find lidar_with_mirror_description)/urdf/sensor/lidar_with_mirror.urdf.xacro" />

  <xacro:lidar_with_mirror name="lidar_with_mirror" parent="lidar_with_mirror_roll_link" right_roll_rad="${radians(70)}" left_pitch_rad="0.0" right_distance_m="0.21" left_roll_rad="${radians(70)}" right_pitch_rad="0.0" left_distance_m="0.21">
    <origin xyz="0 0 0" rpy="0 0 0"/>
  </xacro:lidar_with_mirror>

  <transmission name="tran1">
    <type>transmission_interface/SimpleTransmission</type>
    <joint name="left_wheel_hinge">
      <hardwareInterface>hardware_interface/VelocityJointInterface</hardwareInterface>
    </joint>
  <actuator name="left_motor">
      <hardwareInterface>hardware_interface/VelocityJointInterface</hardwareInterface>
      <mechanicalReduction>1</mechanicalReduction>
    </actuator>
  </transmission>

  <transmission name="tran2">
    <type>transmission_interface/SimpleTransmission</type>
    <joint name="right_wheel_hinge">
      <hardwareInterface>hardware_interface/VelocityJointInterface</hardwareInterface>
    </joint>  
  <actuator name="right_motor">
      <hardwareInterface>hardware_interface/VelocityJointInterface</hardwareInterface>
      <mechanicalReduction>1</mechanicalReduction>
    </actuator>
  </transmission>

  <transmission name="tran3">
    <type>transmission_interface/SimpleTransmission</type>
    <joint name="lidar_with_mirror_pitch_joint">
      <hardwareInterface>hardware_interface/PositionJointInterface</hardwareInterface>
    </joint>
  <actuator name="lidar_with_mirror_pitch_motor">
      <hardwareInterface>hardware_interface/PositionJointInterface</hardwareInterface>
      <mechanicalReduction>1</mechanicalReduction>
    </actuator>
  </transmission>

  <transmission name="tran4">
    <type>transmission_interface/SimpleTransmission</type>
    <joint name="lidar_with_mirror_roll_joint">
      <hardwareInterface>hardware_interface/PositionJointInterface</hardwareInterface>
    </joint>
  <actuator name="lidar_with_mirror_roll_motor">
      <hardwareInterface>hardware_interface/PositionJointInterface</hardwareInterface>
      <mechanicalReduction>1</mechanicalReduction>
    </actuator>
  </transmission>

  <transmission name="tran7">
    <type>transmission_interface/SimpleTransmission</type>
    <joint name="lidar_with_mirror_prismatic_joint">
      <hardwareInterface>hardware_interface/PositionJointInterface</hardwareInterface>
    </joint>
  <actuator name="lidar_with_mirror_prismatic_motor">
      <hardwareInterface>hardware_interface/PositionJointInterface</hardwareInterface>
      <mechanicalReduction>1</mechanicalReduction>
    </actuator>
  </transmission>

  <transmission name="tran8">
    <type>transmission_interface/SimpleTransmission</type>
    <joint name="caster_front_joint">
      <hardwareInterface>hardware_interface/PositionJointInterface</hardwareInterface>
    </joint>
  <actuator name="caster_front_motor">
      <hardwareInterface>hardware_interface/PositionJointInterface</hardwareInterface>
      <mechanicalReduction>1</mechanicalReduction>
    </actuator>
  </transmission>

  <transmission name="tran9">
    <type>transmission_interface/SimpleTransmission</type>
    <joint name="wheel_hinge">
      <hardwareInterface>hardware_interface/PositionJointInterface</hardwareInterface>
    </joint>
  <actuator name="wheel_hinge_motor">
      <hardwareInterface>hardware_interface/PositionJointInterface</hardwareInterface>
      <mechanicalReduction>1</mechanicalReduction>
    </actuator>
  </transmission>

</robot>
